Traceback (most recent call last):
  File "/opt/anaconda3/lib/python3.12/site-packages/jupyter_cache/executors/utils.py", line 58, in single_nb_execution
    executenb(
  File "/opt/anaconda3/lib/python3.12/site-packages/nbclient/client.py", line 1305, in execute
    return NotebookClient(nb=nb, resources=resources, km=km, **kwargs).execute()
           ^^^^^^^^^^^^^^^^^^^^^^^^^^^^^^^^^^^^^^^^^^^^^^^^^^^^^^^^^^^^^^^^^^^^^
  File "/opt/anaconda3/lib/python3.12/site-packages/jupyter_core/utils/__init__.py", line 165, in wrapped
    return loop.run_until_complete(inner)
           ^^^^^^^^^^^^^^^^^^^^^^^^^^^^^^
  File "/opt/anaconda3/lib/python3.12/asyncio/base_events.py", line 685, in run_until_complete
    return future.result()
           ^^^^^^^^^^^^^^^
  File "/opt/anaconda3/lib/python3.12/site-packages/nbclient/client.py", line 705, in async_execute
    await self.async_execute_cell(
  File "/opt/anaconda3/lib/python3.12/site-packages/nbclient/client.py", line 1058, in async_execute_cell
    await self._check_raise_for_error(cell, cell_index, exec_reply)
  File "/opt/anaconda3/lib/python3.12/site-packages/nbclient/client.py", line 914, in _check_raise_for_error
    raise CellExecutionError.from_cell_and_msg(cell, exec_reply_content)
nbclient.exceptions.CellExecutionError: An error occurred while executing the following cell:
------------------
import pandas as pd
------------------


ArgumentError: Package pandas not found in current path.
- Run `import Pkg; Pkg.add("pandas")` to install the pandas package.

Stacktrace:
 [1] macro expansion
   @ ./loading.jl:2296 [inlined]
 [2] macro expansion
   @ ./lock.jl:273 [inlined]
 [3] __require(into::Module, mod::Symbol)
   @ Base ./loading.jl:2271
 [4] #invoke_in_world#3
   @ ./essentials.jl:1089 [inlined]
 [5] invoke_in_world
   @ ./essentials.jl:1086 [inlined]
 [6] require(into::Module, mod::Symbol)
   @ Base ./loading.jl:2260

